Workbook
Name standard1: Std1csv!$B$2:$E$94
Name std2_: Std2csv!$B$2:$E$94
Name std3_: Std3csv!$B$2:$E$94
Name std4_: Std4csv!$B$2:$E$94

Sheet Thermo
B2: Calibration Curve | J2: FeSO4 standard Info
J3: Mass of FeSO4 7H2O used | K3: Conc of Fe2+(M)
J4: 0.0352 | K4: 0.00253
B5: Solution # | C5: Conc Fe2+ in standard (M) | D5: Abs at 597nm | E5: Vol of Stock (µL) | G5: Fe3+ conc in FRAP (mM)
B6: Blank | C6: 0 | D6: 0 | E6: 0 | G6: 0.167
B7: 1 | C7: =($K$4*E7)/(50*10^(3)) -> 6.072e-06 | D7: 0.129 | E7: 120
B8: 2 | C8: =($K$4*E8)/(50*10^(3)) -> 1.2144e-05 | D8: 0.261 | E8: 240
B9: 3 | C9: =($K$4*E9)/(50*10^(3)) -> 1.8216e-05 | D9: 0.4 | E9: 360
B10: 4 | C10: =($K$4*E10)/(50*10^(3)) -> 2.4288e-05 | D10: 0.531 | E10: 480
B11: 5 | C11: =($K$4*E11)/(50*10^(3)) -> 3.036e-05 | D11: 0.657 | E11: 600
B14: Samples | C14: Abs at 597nm | D14: Concentration(µM) | E14: 95% CI (±) (Abs) | F14: %Fe3+ reduced | G14: 95% CI | J14: Molar Absortivity Fe(TPTZ)2 2+ (L mol^-1 cm^-1) | K14: Error (±) | L14: ± CI (95%)
B15: Cranberry | C15: 0.128 | D15: =((C15-$C$36)/$C$37)*10^6 -> 5.9233693 | E15: =(3.18*($C$26/ABS($C$37)) * SQRT(1/COUNT(C15)+1/COUNT($B$6:$B$11)+($D$37^2 * (C15-AVERAGE($D$6:$D$11)^2))/($C$37^2 * $C$26^2)))*10^6 -> 0.57943348 | F15: =D15/($G$6*10^3) *100 -> 3.5469277 | G15: =E15/($G$6*10^3)*100 -> 0.34696616 | J15: =$C$37 -> 21786.185 | K15: =$D$37 -> 139.05615 | L15: =K15*4 -> 556.22461
B16: Green Tea | C16: 0.375 | D16: =((C16-$C$36)/$C$37)*10^6 -> 17.260829 | E16: =(3.18*($C$26/ABS($C$37)) * SQRT(1/COUNT(C16)+1/COUNT($B$6:$B$11)+($D$37^2 * (C16-AVERAGE($D$6:$D$11)^2))/($C$37^2 * $C$26^2)))*10^6 -> 0.7417104 | F16: =D16/($G$6*10^3) *100 -> 10.335826 | G16: =E16/($G$6*10^3)*100 -> 0.44413797
B17: Cloves | C17: 0.117 | D17: =((C17-$C$36)/$C$37)*10^6 -> 5.4184622 | E17: =(3.18*($C$26/ABS($C$37)) * SQRT(1/COUNT(C17)+1/COUNT($B$6:$B$11)+($D$37^2 * (C17-AVERAGE($D$6:$D$11)^2))/($C$37^2 * $C$26^2)))*10^6 -> 0.57113516 | F17: =D17/($G$6*10^3) *100 -> 3.2445881 | G17: =E17/($G$6*10^3)*100 -> 0.3419971
B20: SUMMARY OUTPUT
B22: Regression Statistics
B23: Multiple R | C23: 0.99991853
B24: R Square | C24: 0.99983707
B25: Adjusted R Square | C25: 0.99979633
B26: Standard Error | C26: 0.0035321651
B27: Observations | C27: 6
B29: ANOVA
C30: df | D30: SS | E30: MS | F30: F | G30: Significance F
B31: Regression | C31: 1 | D31: 0.30624143 | E31: 0.30624143 | F31: 24546.069 | G31: 9.9556453e-09
B32: Residual | C32: 4 | D32: 4.9904762e-05 | E32: 1.247619e-05
B33: Total | C33: 5 | D33: 0.30629133
C35: Coefficients | D35: Standard Error | E35: t Stat | F35: P-value | G35: Lower 95% | H35: Upper 95% | I35: Lower 95.0% | J35: Upper 95.0%
B36: Intercept | C36: -0.001047619 | D36: 0.0025563934 | E36: -0.40980353 | F36: 0.70294714 | G36: -0.0081453051 | H36: 0.006050067 | I36: -0.0081453051 | J36: 0.006050067
B37: X Variable 1 | C37: 21786.185 | D37: 139.05615 | E37: 156.67185 | F37: 9.9556453e-09 | G37: 21400.103 | H37: 22172.267 | I37: 21400.103 | J37: 22172.267

Sheet Kinetics
B2: Ascorbic Acid Stock (M)
B3: 0.01254
B5: Solution # | C5: Conc (mM) | D5: Rate (mM min^-1) | E5: Log Conc | F5: Log Rate | G5: Rate Constant (a=1) | I5: Rate Order | J5: Rate Constant (from calibration curve) | K5: Rate Std Dev
B6: 1 | C6: =($B$3*(1/25)*(10/(300+1500+10+800)))*1000 -> 0.0019218391 | D6: =Std1csv!$F$37 -> 0.13317101 | E6: =LOG10(C6) -> -2.716283 | F6: =LOG10(D6) -> -0.87559031 | G6: =10^(F6-E6) -> 69.293527 | I6: =C30 -> 1.1694709 | J6: =10^C29 -> 192.10903 | K6: =J6*LN(10)*D29 -> 87.318395
B7: 2 | C7: =($B$3*(2.265/25)*(10/(300+1500+10+800)))*1000 -> 0.0043529655 | D7: =Std2csv!$F$37 -> 0.31021873 | E7: =LOG10(C7) -> -2.3612148 | F7: =LOG10(D7) -> -0.50833199 | G7: =10^(F7-E7) -> 71.266065
B8: 3 | C8: =($B$3*(3.595/25)*(10/(300+1500+10+800)))*1000 -> 0.0069090115 | D8: =Std3csv!$F$37 -> 0.53734854 | E8: =LOG10(C8) -> -2.1605841 | F8: =LOG10(D8) -> -0.26974393 | G8: =10^(F8-E8) -> 77.775025
B9: 4 | C9: =($B$3*(4.43/25)*(10/(300+1500+10+800)))*1000 -> 0.0085137471 | D9: =Std4csv!$F$37 -> 0.79885502 | E9: =LOG10(C9) -> -2.0698793 | F9: =LOG10(D9) -> -0.09753203 | G9: =10^(F9-E9) -> 93.83119
G10: Average rate constant | H10: 95% CI (±)
G11: =AVERAGE(G6:G9) -> 78.041452 | H11: =(3.18*STDEV(G6:G9))/SQRT(COUNT($B$6:$B$9)) -> 17.70118
B13: SUMMARY OUTPUT
B15: Regression Statistics
B16: Multiple R | C16: 0.99483787
B17: R Square | C17: 0.9897024
B18: Adjusted R Square | C18: 0.98455359
B19: Standard Error | C19: 0.041880691
B20: Observations | C20: 4
B22: ANOVA
C23: df | D23: SS | E23: MS | F23: F | G23: Significance F
B24: Regression | C24: 1 | D24: 0.33715227 | E24: 0.33715227 | F24: 192.21992 | G24: 0.0051621261
B25: Residual | C25: 2 | D25: 0.0035079846 | E25: 0.0017539923
B26: Total | C26: 3 | D26: 0.34066025
C28: Coefficients | D28: Standard Error | E28: t Stat | F28: P-value | G28: Lower 95% | H28: Upper 95% | I28: Lower 95.0% | J28: Upper 95.0%
B29: Intercept | C29: 2.2835478 | D29: 0.19739778 | E29: 11.568254 | F29: 0.0073897456 | G29: 1.4342137 | H29: 3.1328819 | I29: 1.4342137 | J29: 3.1328819
B30: X Variable 1 | C30: 1.1694709 | D30: 0.084350995 | E30: 13.86434 | F30: 0.0051621261 | G30: 0.80653784 | H30: 1.5324039 | I30: 0.80653784 | J30: 1.5324039

Sheet Std1csv
B2: Kinetics | D2: 04/11/2025 17:58:57
B3: Lambda XLS+ | C3: 2585
B4: 04/11/2025 | C4: 0.74927083
B5: Product | C5: Lambda XLS+
B6: Version | C6: 8283 V1.1.0
B7: Serial Number | C7: 2585
B8: Date | C8: 45965
B9: Time | C9: 0.74863426
B10: Instrument Calibration Pass
B11: 45965.7
B12: Wavelength | C12: 597 nm
B13: Factor | C13: 1
B14: Units
B15: Mode | C15: Final A
B16: Delay Time | C16: 2 Seconds
B17: Duration | C17: 1 Minutes
B18: Interval | C18: 1 Seconds
B19: Data Points | C19: 60
B21: Sample | C21: 2
B22: A0 | C22: An | D22: dA
B23: A | C23: A | D23: A
B24: 0.027 | C24: 0 | D24: 0.027
B26: Slope | C26: Result | D26: R2
B27: dA/m
B28: -0.061 | C28: 0 | D28: 0.2483
B29: Cursor | C29: Absorbance
B30: hh:mm:ss | C30: A
B31: 0.00034722222 | C31: 0.095
B32: Time (Minutes) | C32: Absorbance (A) | D32: Time (Minutes) | E32: Absorbance (A)
B33: 0 | C33: 0.0270802 | D33: 0.5 | E33: -0.2
B34: 0.0166667 | C34: 0.0754351 | D34: 0.5 | E34: 0.301124
B35: 0.0333334 | C35: 0.0733296
B36: 0.0500001 | C36: 0.0760635 | F36: INITIAL RATE
B37: 0.0666668 | C37: 0.0762429 | F37: =((C34-C33)/(B34*Thermo!J15))*1000 -> 0.13317101
B38: 0.08333349 | C38: 0.0772974
B39: 0.1000002 | C39: 0.0786916
B40: 0.1166669 | C40: 0.0780807
B41: 0.1333336 | C41: 0.0813127
B42: 0.1500003 | C42: 0.0818372
B43: 0.166667 | C43: 0.0821665
...

Sheet Std2csv
B2: Kinetics | D2: 04/11/2025 18:05:42
B3: Lambda XLS+ | C3: 2585
B4: 04/11/2025 | C4: 0.75395833
B5: Product | C5: Lambda XLS+
B6: Version | C6: 8283 V1.1.0
B7: Serial Number | C7: 2585
B8: Date | C8: 45965
B9: Time | C9: 0.75333333
B10: Instrument Calibration Pass
B11: 45965.7
B12: Wavelength | C12: 597 nm
B13: Factor | C13: 1
B14: Units
B15: Mode | C15: Final A
B16: Delay Time | C16: 2 Seconds
B17: Duration | C17: 1 Minutes
B18: Interval | C18: 1 Seconds
B19: Data Points | C19: 60
B21: Sample | C21: 4
B22: A0 | C22: An | D22: dA
B23: A | C23: A | D23: A
B24: 0.062 | C24: 0 | D24: 0.062
B26: Slope | C26: Result | D26: R2
B27: dA/m
B28: -0.16 | C28: 0 | D28: 0.3899
B29: Cursor | C29: Absorbance
B30: hh:mm:ss | C30: A
B31: 0.00034722222 | C31: 0.184
B32: Time (Minutes) | C32: Absorbance (A) | D32: Time (Minutes) | E32: Absorbance (A)
B33: 0 | C33: 0.0621994 | D33: 0.5 | E33: -0.2
B34: 0.0166667 | C34: 0.174841 | D34: 0.5 | E34: 0.392378
B35: 0.0333334 | C35: 0.17307
B36: 0.0500001 | C36: 0.172063 | F36: INITIAL RATE
B37: 0.0666668 | C37: 0.171649 | F37: =((C34-C33)/(B34*Thermo!J15))*1000 -> 0.31021873
B38: 0.08333349 | C38: 0.175147
B39: 0.1000002 | C39: 0.176008
B40: 0.1166669 | C40: 0.176271
B41: 0.1333336 | C41: 0.176196
B42: 0.1500003 | C42: 0.181646
B43: 0.166667 | C43: 0.183253
...

Sheet Std3csv
B2: Kinetics | D2: 04/11/2025 18:13:17
B3: Lambda XLS+ | C3: 2585
B4: 04/11/2025 | C4: 0.75922454
B5: Product | C5: Lambda XLS+
B6: Version | C6: 8283 V1.1.0
B7: Serial Number | C7: 2585
B8: Date | C8: 45965
B9: Time | C9: 0.75858796
B10: Instrument Calibration Pass
B11: 45965.7
B12: Wavelength | C12: 597 nm
B13: Factor | C13: 1
B14: Units
B15: Mode | C15: Final A
B16: Delay Time | C16: 2 Seconds
B17: Duration | C17: 1 Minutes
B18: Interval | C18: 1 Seconds
B19: Data Points | C19: 60
B21: Sample | C21: 5
B22: A0 | C22: An | D22: dA
B23: A | C23: A | D23: A
B24: 0.037 | C24: 0 | D24: 0.037
B26: Slope | C26: Result | D26: R2
B27: dA/m
B28: -0.24 | C28: 0 | D28: 0.3674
B29: Cursor | C29: Absorbance
B30: hh:mm:ss | C30: A
B31: 0.00034722222 | C31: 0.281
B32: Time (Minutes) | C32: Absorbance (A) | D32: Time (Minutes) | E32: Absorbance (A)
B33: 0 | C33: 0.0373327 | D33: 0.5 | E33: 0
B34: 0.0166667 | C34: 0.232446 | D34: 0.5 | E34: 0.288781
B35: 0.0333334 | C35: 0.25216
B36: 0.0500001 | C36: 0.263933 | F36: INITIAL RATE
B37: 0.0666668 | C37: 0.271156 | F37: =((C34-C33)/(B34*Thermo!J15))*1000 -> 0.53734854
B38: 0.08333349 | C38: 0.27341
B39: 0.1000002 | C39: 0.274637
B40: 0.1166669 | C40: 0.272709
B41: 0.1333336 | C41: 0.267255
B42: 0.1500003 | C42: 0.266676
B43: 0.166667 | C43: 0.27189
...

Sheet Std4csv
B2: Kinetics | D2: 04/11/2025 18:16:14
B3: Lambda XLS+ | C3: 2585
B4: 04/11/2025 | C4: 0.76127315
B5: Product | C5: Lambda XLS+
B6: Version | C6: 8283 V1.1.0
B7: Serial Number | C7: 2585
B8: Date | C8: 45965
B9: Time | C9: 0.76065972
B10: Instrument Calibration Pass
B11: 45965.7
B12: Wavelength | C12: 597 nm
B13: Factor | C13: 1
B14: Units
B15: Mode | C15: Final A
B16: Delay Time | C16: 2 Seconds
B17: Duration | C17: 1 Minutes
B18: Interval | C18: 1 Seconds
B19: Data Points | C19: 60
B21: Sample | C21: 6
B22: A0 | C22: An | D22: dA
B23: A | C23: A | D23: A
B24: 0.021 | C24: 0 | D24: 0.021
B26: Slope | C26: Result | D26: R2
B27: dA/m
B28: -0.318 | C28: 0 | D28: 0.3762
B29: Cursor | C29: Absorbance
B30: hh:mm:ss | C30: A
B31: 0.00034722222 | C31: 0.358
B32: Time (Minutes) | C32: Absorbance (A) | D32: Time (Minutes) | E32: Absorbance (A)
B33: 0 | C33: 0.0210317 | D33: 0.5 | E33: 0
B34: 0.0166667 | C34: 0.311099 | D34: 0.5 | E34: 0.372317
B35: 0.0333334 | C35: 0.340434
B36: 0.0500001 | C36: 0.35397 | F36: INITIAL RATE
B37: 0.0666668 | C37: 0.35188 | F37: =((C34-C33)/(B34*Thermo!J15))*1000 -> 0.79885502
B38: 0.08333349 | C38: 0.35521
B39: 0.1000002 | C39: 0.356555
B40: 0.1166669 | C40: 0.354967
B41: 0.1333336 | C41: 0.358315
B42: 0.1500003 | C42: 0.363207
B43: 0.166667 | C43: 0.363828
...
